Workbook

Sheet Bitacora
B2: PENALIZACION NIVEL DE SERVICIO ENE - AGO 2025 | D2: =D5-W5 -> 3.207253e+08 | H2: =H5-J5 -> 1.936889e+08 | K2: =K5-D7-D8 -> 1.9389838e+08 | S2: =R5-W5 -> 5874640.1
B3: Autorizado por direcciones comerciales | W3: =D5-W5 -> 3.207253e+08
G4: =G5-Z5-G7-G8 -> 2.184201e+08 | H4: =G9-H9 -> 1637510.6 | S4: =D4-O4-W4 -> 0 | T4: =E4-X4-P4 -> 0 | U4: =F4-Y4-Q4 -> 0
C5: =SUBTOTAL(3,C7:C438) -> 432 | D5: =SUBTOTAL(9,D7:D438) -> 3.6979601e+08 | E5: =SUBTOTAL(9,E7:E438) -> 6790563.2 | F5: =SUBTOTAL(9,F7:F438) -> 39326912 | G5: =SUBTOTAL(9,G7:G438) -> 4.1591348e+08 | H5: =SUBTOTAL(9,H7:H438) -> 1.936889e+08 | I5: =SUBTOTAL(9,I7:I438) -> 3.2065458e+08 | J5: =SUBTOTAL(9,J7:J438) -> 0 | K5: =SUBTOTAL(9,K7:K438) -> 3.2065458e+08 | ... Z5: =SUBTOTAL(9,Z7:Z438) -> 57208713 | AC5: =SUBTOTAL(9,AC7:AC438) -> 3.6979601e+08 | AD5: =SUBTOTAL(9,AD7:AD438) -> 4.1602438e+08 | AE5: =SUBTOTAL(9,AE7:AE438) -> -110898.08 | AN5: =SUBTOTAL(9,AN7:AN438) -> 2.1767891e+08 | AP5: =SUBTOTAL(9,AP7:AP1048576) -> 152 | AR5: =SUBTOTAL(3,AR7:AR1048576) -> 75 | AX5: Forma de contacto proveedor
B6: Proveedor | C6: Nombre | D6: Cargo Publicado en Portal | E6: IEPS | F6: IVA | G6: Penalizacion con Imptos | H6: Aplicado en cuenta de proveedor (incluye imptos) | I6: total por aplicar (antes imptos) | J6: Reembolso (antes imptos) | K6: Final (antes imptos) | L6: total por aplicar (inlcuye imtpos) | M6: Reembolso con Imptos | N6: Final con imptos | O6: Aceptado (antes impto) | P6: IEPS aceptado | Q6: IVA aceptado | R6: Aceptado con Imptos | S6: Pendiente (antes impto) | T6: IEPS pendiente | U6: IVA pendiente | V6: Pendiente con Imptos | W6: Soportado (no procede antes impto) | X6: IEPS no procede | Y6: IVA no procede | Z6: Soportado con Imptos | AA6: NS 2020-2024 antes de impuestos | AB6: Tipo Proveedor | AC6: TOTAL (antes impto) | AD6: TOTAL (con impto) | AE6: dif | AF6: Parcialidad | AG6: Accionable | AH6: Avisos en Portal | AI6: Correos de seguimiento | AJ6: Observación actual | AK6: contacto | AL6: ESTATUS_1 | AM6: Asignación | AN6: Importe reclama proveedor | AO6: Solicita Proveedor en aclaración | AP6: Folios en aclaración | AQ6: Soporte en poratl | AR6: Fecha Contacto | AS6: Fecha se envió detalle | AT6: Confirmacion recibo | AU6: Fecha reunión | AV6: Comentarios | AW6: ESTATUS | AX6: Aclaracion Portal | AY6: Correo auditor | AZ6: Comercial | BA6: Observacion | BB6: Liga contacto
B7: 66738 | C7: MONDELEZ MEXICO S DE RL DE CV | D7: 89585265 | E7: 2507350.6 | F7: 5074446 | G7: 97167062 | H7: 0 | I7: =O7+S7 -> 89585265 | K7: =I7-J7 -> 89585265 | L7: =R7+V7 -> 97167062 | N7: =L7-M7 -> 97167062 | R7: =SUM(O7:Q7) -> 0 | S7: =D7-O7-W7 -> 89585265 | T7: =E7-X7-P7 -> 2507350.6 | U7: =F7-Y7-Q7 -> 5074446 | V7: =SUM(S7:U7) -> 97167062 | Z7: =SUM(W7:Y7) -> 0 | AA7: 72733062 | AB7: TOP - Aclaracion | AC7: =O7+S7+W7 -> 89585265 | AD7: =R7+V7+Z7 -> 97167062 | AE7: =G7-AD7 -> -0.10609704 | AF7: =D7-S7 -> 0 | AG7: Revisión | AH7: 4 | AI7: 3 | AJ7: Proveedor indica se validará con Dirección el saldo de esta Auditoria. | AK7: CON CONTACTO | AL7: DEFINICION FINANZAS | AM7: Perla | AN7: 97167062 | AR7: 46041 | AS7: 46041 | AV7: En validaciòn por parte de Proveedor, se tiene programada reuniòn el 26 de enero, en espera de confirmaciòn de horario. Negativa de proveedor. | BA7: En validaciòn por parte de Proveedor, se tiene programada reuniòn el 26 de enero, en espera de confirmaciòn de horario. | BB7: =VLOOKUP(B7,contactos!$A$1:$D$484,4,FALSE) -> julioarturo.gomez@mdlz.com
B8: 9647 | C8: FRABEL S.A. DE C.V. | D8: 37170940 | E8: 0 | F8: 5946668.2 | G8: 43117610 | H8: 0 | I8: =O8+S8 -> 37170940 | K8: =I8-J8 -> 37170940 | L8: =R8+V8 -> 43117608 | N8: =L8-M8 -> 43117608 | R8: =SUM(O8:Q8) -> 0 | S8: =D8-O8-W8 -> 37170940 | T8: =E8-X8-P8 -> 0 | U8: =F8-Y8-Q8 -> 5946668.2 | V8: =SUM(S8:U8) -> 43117608 | Z8: =SUM(W8:Y8) -> 0 | AA8: 1.5056482e+08 | AB8: TOP - Aclaracion | AC8: =O8+S8+W8 -> 37170940 | AD8: =R8+V8+Z8 -> 43117608 | AE8: =G8-AD8 -> 1.3499264 | AF8: =D8-S8 -> 0 | AG8: Revisión | AH8: 4 | AI8: 3 | AJ8: Tema interno | AK8: CON CONTACTO | AL8: NEGATIVA ACLARACIONES | AM8: Raul | AN8: 43117609 | AO8: DETALLE DE LOS CARGOS EN EL PORTAL | AR8: 46043 | AS8: 46043 | AV8: Se le aclara a proveedor el periodo de revisión | AW8: Casos abiertos( En proceso) | AX8: X | BB8: =VLOOKUP(B8,contactos!$A$1:$D$484,4,FALSE) -> pablo.candelas@loreal.com
B9: 24232 | C9: GRISI HNOS SA DE CV | D9: 17089111 | E9: 15021.684 | F9: 2502789.4 | G9: 19606922 | H9: 17969411 | I9: =O9+S9 -> 16495305 | K9: =I9-J9 -> 16495305 | L9: =R9+V9 -> 18918922 | N9: =L9-M9 -> 18918922 | O9: 2911551.2 | P9: 0 | Q9: 325961.06 | R9: =SUM(O9:Q9) -> 3237512.2 | S9: =D9-O9-W9 -> 13583754 | T9: =E9-X9-P9 -> 15021.684 | U9: =F9-Y9-Q9 -> 2082634.2 | V9: =SUM(S9:U9) -> 15681410 | W9: 593806.06 | X9: 0 | Y9: 94194.14 | Z9: =SUM(W9:Y9) -> 688000.2 | AA9: 19425853 | AB9: TOP - Aclaracion | AC9: =O9+S9+W9 -> 17089111 | AD9: =R9+V9+Z9 -> 19606922 | AE9: =G9-AD9 -> -0.50646909 | AG9: Aplicar | AH9: 4 | AI9: 10 | AJ9: 20-feb-2026 se comparte con proveedor saldo improcedente por 688K de acuerdo con soportes validados, en espera de soportes y respuesta del saldo restante (proveedor manda correo a Dir Comercial con la afectación al margen en caso de que se cobre el saldo) | AK9: CON CONTACTO | AL9: PDTE POR PROVEEDOR | AM9: Samuel | AO9: SOLICITA DETALLE DE 3 RAZONES QUE MANEJA (GRISI,COMBE,DIGRIMEX) | AR9: 46042 | AS9: 46042 | AV9: Proveedor pide prorroga | AY9: X | BA9: Se revisan evidencias enviadas por proveedor, pero no soportan la imprcedencia del saldo | BB9: =VLOOKUP(B9,contactos!$A$1:$D$484,4,FALSE) -> alberto.saenz@grisi.com
B10: 4077 | C10: BDF MEXICO S.A DE C.V | D10: 15564009 | E10: 0 | F10: 2488527.7 | G10: 18052536 | H10: 18052536 | I10: =O10+S10 -> 15564009 | K10: =I10-J10 -> 15564009 | L10: =R10+V10 -> 18052537 | N10: =L10-M10 -> 18052537 | O10: =D10 -> 15564009 | P10: 0 | Q10: =F10 -> 2488527.7 | R10: =SUM(O10:Q10) -> 18052537 | S10: =D10-O10-W10 -> 0 | T10: =E10-X10-P10 -> 0 | U10: =F10-Y10-Q10 -> 0 | V10: =SUM(S10:U10) -> 0 | Z10: =SUM(W10:Y10) -> 0 | AA10: 24076668 | AB10: TOP - Aclaracion | AC10: =O10+S10+W10 -> 15564009 | AD10: =R10+V10+Z10 -> 18052537 | AE10: =G10-AD10 -> -0.34516056 | AG10: Cerrado/Aplicar | AH10: 4 | AI10: 0 | AJ10: 0 | AK10: CON CONTACTO | AL10: CERRADO | AM10: Yessenia | AN10: 18052536 | AO10: DETALLE DE LOS CARGOS EN EL PORTAL | AR10: 46045 | AS10: 46045 | AV10: Proveedor acepta parte del monto $18,022,712.44 y quedado es espera de soporte de no aceptado de $29,823.79 | AW10: Casos cerrados | AX10: X | BA10: correo compartido por Ambriz Ruiz Jair Alejandro <jairar@soriana.com> | BB10: =VLOOKUP(B10,contactos!$A$1:$D$484,4,FALSE) -> josemiguel.migoya@beiersdorf.com
B11: 76471 | C11: NEWELL BRANDS DE MEXICO SA DE CV | D11: 11585559 | E11: 0 | F11: 1853689.4 | G11: 13439248 | H11: 13439248 | I11: =O11+S11 -> 4720981.4 | J11: 0 | K11: =I11-J11 -> 4720981.4 | L11: =R11+V11 -> 5476338.4 | M11: 0 | N11: =L11-M11 -> 5476338.4 | R11: =SUM(O11:Q11) -> 0 | S11: =D11-O11-W11 -> 4720981.4 | T11: =E11-X11-P11 -> 0 | U11: =F11-Y11-Q11 -> 755357.03 | V11: =SUM(S11:U11) -> 5476338.4 | W11: 6864577.3 | X11: 0 | Y11: =W11*0.16 -> 1098332.4 | Z11: =SUM(W11:Y11) -> 7962909.7 | AA11: 22858397 | AB11: TOP - Sin aclaracion | AC11: =O11+S11+W11 -> 11585559 | AD11: =R11+V11+Z11 -> 13439248 | AE11: =G11-AD11 -> -0.11216746 | AF11: =D11-S11 -> 6864577.3 | AG11: Aplicar | AH11: 4 | AI11: 1 | AJ11: Sin comentarios del proveedor. | AK11: CON CONTACTO | AL11: SIN ACLARACION | AM11: Olfi | AS11: 46050 | AV11: Se le manda correo al proveedor, informandole sobre la auditoria del 2025 | BB11: =VLOOKUP(B11,contactos!$A$1:$D$484,4,FALSE) -> luis.quesadamoreno@newellco.com
B12: 99457 | C12: ESSITY HIGIENE Y SALUD MEXICO SA DE | D12: 10217048 | E12: 0 | F12: 959842.67 | G12: 11176891 | H12: 2355255 | I12: =O12+S12 -> 2126670.9 | K12: =I12-J12 -> 2126670.9 | L12: =R12+V12 -> 2355254.9 | N12: =L12-M12 -> 2355254.9 | O12: 2126670.9 | Q12: 228584.06 | R12: =SUM(O12:Q12) -> 2355254.9 | S12: =D12-O12-W12 -> 0.0024101967 | T12: =E12-X12-P12 -> 0 | U12: =F12-Y12-Q12 -> -0.00067947659 | V12: =SUM(S12:U12) -> 0.0017307201 | W12: 8090377.5 | Y12: 731258.61 | Z12: =SUM(W12:Y12) -> 8821636.1 | AA12: 15169011 | AB12: TOP - Aclaracion | AC12: =O12+S12+W12 -> 10217048 | AD12: =R12+V12+Z12 -> 11176891 | AE12: =G12-AD12 -> -0.37633072 | AG12: Cerrado/Aplicar | AH12: 4 | AI12: 0 | AJ12: 0 | AK12: CON CONTACTO | AL12: CERRADO | AM12: Luis | AN12: 9215790.6 | AR12: 46049 | AS12: 46049 | AT12: 46049 | AV12: Proveedor se contacta con Ana Ruth/Ruben/Tere para solicitar prórroga de los saldos publicados en portal | AX12: X | BB12: =VLOOKUP(B12,contactos!$A$1:$D$484,4,FALSE) -> antonio.palacios@essity.com
B13: 8593 | C13: VISION COMERCIAL DEPORTIVA SA DE CV | D13: 8613844.6 | E13: 0 | F13: 1378215.1 | G13: 9992059.6 | H13: 9992059.6 | I13: =O13+S13 -> 3291014.8 | J13: 0 | K13: =I13-J13 -> 3291014.8 | L13: =R13+V13 -> 3817577.2 | M13: 0 | N13: =L13-M13 -> 3817577.2 | R13: =SUM(O13:Q13) -> 0 | S13: =D13-O13-W13 -> 3291014.8 | T13: =E13-X13-P13 -> 0 | U13: =F13-Y13-Q13 -> 526562.37 | V13: =SUM(S13:U13) -> 3817577.2 | W13: 5322829.8 | Y13: 851652.77 | Z13: =SUM(W13:Y13) -> 6174482.6 | AA13: 6020406 | AB13: TOP - Aclaracion | AC13: =O13+S13+W13 -> 8613844.6 | AD13: =R13+V13+Z13 -> 9992059.8 | AE13: =G13-AD13 -> -0.15727409 | AF13: =D13-S13 -> 5322829.8 | AG13: Aplicar | AH13: 4 | AI13: 8 | AJ13: Proveedor menciona tiene reunión con dirección comercial Soriana el 19 de febrero. Al dia de hoy sin comentarios o soportes por parte del proveedor. | AK13: CON CONTACTO | AL13: PDTE POR PROVEEDOR | AM13: Samuel | AN13: 9992059.6 | AO13: CARGOS YA APLICADOS ANTERIORMENTE (CARGO IMPROCEDENTE) | AP13: 11 | AR13: 46042 | AS13: 46045 | AV13: En validación de información, proveedor solicita reunión 28-ene-26. Proveedor argumenta que los cargos no proceden porque le han hecho otros cargos improcedentes. | AX13: X | BB13: =VLOOKUP(B13,contactos!$A$1:$D$484,4,FALSE) -> victorsanchez@wsports.mx
B14: 90738 | C14: ESSITY HIGIENE Y SALUD MEXICO SA DE | D14: 7245863.5 | E14: 0 | F14: 1159338.2 | G14: 8405201.7 | H14: 3749488 | I14: =O14+S14 -> 3232317.2 | K14: =I14-J14 -> 3232317.2 | L14: =R14+V14 -> 3749488.2 | N14: =L14-M14 -> 3749488.2 | O14: 3232317.2 | Q14: 517170.75 | R14: =SUM(O14:Q14) -> 3749488 | S14: =D14-O14-W14 -> -0.002259267 | T14: =E14-X14-P14 -> 0 | U14: =F14-Y14-Q14 -> 0.21754143 | V14: =SUM(S14:U14) -> 0.21528216 | W14: 4013546.3 | Y14: 642167.2 | Z14: =SUM(W14:Y14) -> 4655713.5 | AA14: 14487404 | AB14: TOP - Aclaracion | AC14: =O14+S14+W14 -> 7245863.5 | AD14: =R14+V14+Z14 -> 8405201.7 | AE14: =G14-AD14 -> -0.0048821624 | AG14: Cerrado/Aplicar | AH14: 4 | AI14: 0 | AJ14: 0 | AK14: CON CONTACTO | AL14: CERRADO | AM14: Luis | AN14: 4650882.8 | AR14: 46049 | AS14: 46049 | AT14: 46049 | AV14: Proveedor se contacta con Ruben/Tere para solicitar prórroga de los saldos publicados en portal | AX14: X | BB14: =VLOOKUP(B14,contactos!$A$1:$D$484,4,FALSE) -> claudia.morales@essity.com
B15: 20125 | C15: MIDEA MEXICO S DE RL DE CV | D15: 7139158.7 | E15: 0 | F15: 1142265.4 | G15: 8281424.2 | H15: 3000000 | I15: =O15+S15 -> 4948440.3 | K15: =I15-J15 -> 4948440.3 | L15: =R15+V15 -> 5740190.7 | N15: =L15-M15 -> 5740190.7 | R15: =SUM(O15:Q15) -> 0 | S15: =D15-O15-W15 -> 4948440.3 | T15: =E15-X15-P15 -> 0 | U15: =F15-Y15-Q15 -> 791750.45 | V15: =SUM(S15:U15) -> 5740190.7 | W15: 2190718.5 | X15: 0 | Y15: 350514.95 | Z15: =SUM(W15:Y15) -> 2541233.4 | AA15: 4964584.1 | AB15: TOP - Sin aclaracion | AC15: =O15+S15+W15 -> 7139158.7 | AD15: =R15+V15+Z15 -> 8281424.1 | AE15: =G15-AD15 -> 0.0020169588 | AG15: Aplicar | AH15: 4 | AI15: 3 | AJ15: 03 Contactos 28 ene: correo de contacto inicial 04 feb: reunión vía TEAMS 06 feb El proveedor envia soportes que desestima $2,541 incluido impuesto. Proveedor solicita 10 días adicionales para recabar el monto $5,740 incluido impuestos. El Proveedor copia área Comercial solicitando apoyo en los 10 días | AK15: CON CONTACTO | AL15: PDTE POR PROVEEDOR | AM15: Andrea | AN15: 544291.47 | AO15: ERROR EN EL CALCULO DEL CARGO SOLICTA EL REEMBOLSO | AP15: 6 | AR15: 46056 | AS15: 46050 | AU15: 46057 | AV15: Se envía correo informando que el comunicado de cargo NS correspondiente al periodo de enero a agosto de 2025 ya se encuentra publicado en el Portal. El detalle del mismo también está disponible desglosado en el Portal. Se adjunta manual de visualizacion de Cargos.//03 FEB el area de Aclaraciones envia correo, se contacta al Proveedor y se realizara reunion el dia 04 feb para revisar el detalle que presenta diferencias y confirmar el monto a favor de Soriana.//04 feb se realiza reunion con Equipo de Midea, quienes presentan diferencias en unidades pedidas segun su sistema, hacemos el ejercicio de revisar puntualmente 5 Ordenes de compra e identifcamos que la cantidad que tiene en su archivo Midea es la real Facturada, por lo que validaran internamente el restante de las ordenes de compra.// 05 feb El proveedor envió correos informando que los camiones permanecieron en el CEDI por más de 30 horas sin que se les pudiera recibir. Asimismo, compartieron un correo con el equipo Comercial de Soriana notificando esta situación y solicitando, por favor, que las órdenes de compra (OC) fueran excluidas de la penalización por nivel de servicio (NS). Proveedor relaciona en excel el valor de $2,541,233.37 pero solo envia soportes de $1,742,928.70// 06 feb El proveedor correo soporte de dos ordenes de compra adicional, por lo tanto no procede el monto de $2.541.233.37 impuestos incluidos. | AW15: Casos abiertos( En proceso) | AX15: X | BB15: =VLOOKUP(B15,contactos!$A$1:$D$484,4,FALSE) -> marco.heredia@midea.com
B16: 56150 | C16: Hershey Mexico SA de CV | D16: 5860104.4 | E16: 417698.04 | F16: 0 | G16: 6277802.3 | H16: 4920449.6 | I16: =O16+S16 -> 4598868.4 | K16: =I16-J16 -> 4598868.4 | L16: =R16+V16 -> 4920449.6 | N16: =L16-M16 -> 4920449.6 | O16: 4598868.4 | P16: 321581.11 | Q16: 0 | R16: =+O16+P16 -> 4920449.6 | S16: 0 | U16: =F16-Q16-Y16 -> 0 | V16: =SUM(S16:U16) -> 0 | W16: =+D16-O16 -> 1261236 | X16: =+E16-P16 -> 96116.929 | Y16: 0 | Z16: =SUM(W16:Y16) -> 1357352.9 | AA16: 17817198 | AB16: TOP - Aclaracion | AC16: =O16+S16+W16 -> 5860104.4 | AD16: =R16+V16+Z16 -> 6277802.5 | AE16: =G16-AD16 -> -0.17458287 | AG16: Cerrado/Aplicar | AH16: 4 | AI16: 0 | AJ16: 0 | AK16: CON CONTACTO | AL16: CERRADO | AM16: Jessica | AN16: 6277802.3 | AO16: DETALLE DE LOS CARGOS EN EL PORTAL | AR16: 46042 | AS16: =TODAY() -> 46212 | AV16: Proveedor acepto de manera parcial, envio soportes para su validacion | AX16: X | BA16: En reunión proveedor nos comenta que ya descargo la información del portal sin embargo requiere la fecha pedido | BB16: =VLOOKUP(B16,contactos!$A$1:$D$484,4,FALSE) -> srosas@hersheys.com
B17: 81653 | C17: HEINZ MEXICO SA DE CV | D17: 5448761.5 | E17: 8396.2742 | F17: 1307.9177 | G17: 5458465.7 | H17: 4134827.1 | I17: =O17+S17 -> 5448761.5 | K17: =I17-J17 -> 5448761.5 | L17: =R17+V17 -> 5458465.7 | N17: =L17-M17 -> 5458465.7 | R17: =SUM(O17:Q17) -> 0 | S17: 5448761.5 | T17: =E17-X17 -> 8396.2742 | U17: =F17-Y17 -> 1307.9177 | V17: =SUM(S17:U17) -> 5458465.7 | Z17: =SUM(W17:Y17) -> 0 | AA17: 4400579.5 | AB17: TOP - Sin aclaracion | AC17: =O17+S17+W17 -> 5448761.5 | AD17: =R17+V17+Z17 -> 5458465.7 | AE17: =G17-AD17 -> -0.017394756 | AF17: =D17-S17 -> 0 | AG17: Aplicar | AH17: 4 | AI17: 1 | AJ17: Sin comentarios del proveedor.(1 correo seguimiento) | AK17: CON CONTACTO | AL17: SIN ACLARACION | AM17: Yessica | AS17: 46050 | AV17: Se envia Manual y detalle NS 2025 | BA17: Se envia Manual y detalle NS 2025 | BB17: =VLOOKUP(B17,contactos!$A$1:$D$484,4,FALSE) -> juan.hernandez@kraftheinz.com
B18: 61713 | C18: MALTA TEXO DE MEXICO SA DE CV | D18: 4432996.1 | E18: 0 | F18: 709279.41 | G18: 5142275.5 | H18: 2790756.5 | I18: =O18+S18 -> 2938945.2 | K18: =I18-J18 -> 2938945.2 | L18: =R18+V18 -> 3409176.4 | N18: =L18-M18 -> 3409176.4 | O18: 2405824.6 | Q18: 384931.93 | R18: =SUM(O18:Q18) -> 2790756.5 | S18: 533120.62 | T18: =E18-X18 -> 0 | U18: =S18*16% -> 85299.299 | V18: =SUM(S18:U18) -> 618419.92 | W18: 1494050.9 | Y18: 239048.17 | Z18: =SUM(W18:Y18) -> 1733099.1 | AA18: 9975341.2 | AB18: TOP - Sin aclaracion | AC18: =O18+S18+W18 -> 4432996.2 | AD18: =R18+V18+Z18 -> 5142275.5 | AE18: =G18-AD18 -> -0.019200001 | AG18: Revisión | AH18: 4 | AI18: 5 | AJ18: Proveedor quedó en compartir evidencia adicional esta semana 23-feb-2026, aprobacion de compras Soriana de omisión de cobros. | AK18: CON CONTACTO | AL18: PDTE POR PROVEEDOR | AM18: Raul | AS18: 46050 | AV18: Se le manda correo al proveedor, informandole sobre la auditoria del 2025 | AW18: Casos abiertos( En proceso) | BB18: =VLOOKUP(B18,contactos!$A$1:$D$484,4,FALSE) -> Oscar Daniel Rios Garcia
B19: 398024 | C19: PINSA COMERCIAL SA DE CV | D19: 4901364.6 | E19: 0 | F19: 0 | G19: 4901364.6 | H19: 4901364.6 | I19: =O19+S19 -> 1444913.9 | J19: 0 | K19: =I19-J19 -> 1444913.9 | L19: =R19+V19 -> 1444913.9 | M19: 0 | N19: =L19-M19 -> 1444913.9 | R19: =SUM(O19:Q19) -> 0 | S19: =G19-W19 -> 1444913.9 | T19: =E19-X19 -> 0 | U19: =F19-Y19 -> 0 | V19: =SUM(S19:U19) -> 1444913.9 | W19: 3456450.7 | Y19: =W19*0 -> 0 | Z19: =SUM(W19:Y19) -> 3456450.7 | AA19: 20851675 | AB19: TOP - Sin aclaracion | AC19: =O19+S19+W19 -> 4901364.6 | AD19: =R19+V19+Z19 -> 4901364.6 | AE19: =G19-AD19 -> 0 | AF19: =D19-S19 -> 3456450.7 | AG19: Aplicar | AH19: 4 | AI19: 1 | AJ19: 0 | AK19: CON CONTACTO | AL19: SIN ACLARACION | AM19: Yessenia | BB19: =VLOOKUP(B19,contactos!$A$1:$D$484,4,FALSE) -> lcedillo@pinsa.com
B20: 34934 | C20: CARVAJAL EDUCACION S.A. DE C.V. | D20: 4076300.2 | E20: 0 | F20: 652208.03 | G20: 4728508.2 | H20: 0 | I20: =O20+S20 -> 1718185 | K20: =I20-J20 -> 1718185 | L20: =R20+V20 -> 1993094.6 | N20: =L20-M20 -> 1993094.6 | O20: 1718185 | P20: 0 | Q20: 274909.6 | R20: =SUM(O20:Q20) -> 1993094.6 | S20: 0 | T20: 0 | U20: =S20*16% -> 0 | V20: =SUM(S20:U20) -> 0 | W20: 2358115 | X20: 0 | Y20: 377298.43 | Z20: =SUM(W20:Y20) -> 2735413.4 | AA20: 11263016 | AB20: TOP - Aclaracion | AC20: =O20+S20+W20 -> 4076300 | AD20: =R20+V20+Z20 -> 4728508 | AE20: =G20-AD20 -> 0.2 | AG20: Revisión | AH20: 4 | AI20: 6 | AJ20: 03-03-2026 - En reunión presencial con el proveedor, este presenta soportes que disminuyen el valor de la diferencia presentada - se hace recalculo y se vuelve a enviar al proveedor para su aceptación 16-feb-2026 se informa a proveedor que el soporte que envia (Oleaje, resurtidos) no especicifa los pedidos publicados. | AK20: CON CONTACTO | AL20: PDTE POR PROVEEDOR | AM20: Marcela | AN20: 4728508.2 | AO20: REEMBOLSO DEL CARGO | AP20: 6 | AR20: 46050 | AS20: 46050 | AV20: Proveedor comparte soportes del no cobro de NS | AX20: X | BB20: =VLOOKUP(B20,contactos!$A$1:$D$484,4,FALSE) -> OMAR.JURADO@CARVAJAL.COM
B21: 38893 | C21: ABSORMEX CMPC TISSUE SA DE CV | D21: 3414125.4 | E21: 0 | F21: 546260.19 | G21: 3960385.4 | H21: 3960385.6 | I21: =O21+S21 -> 3414125.4 | K21: =I21-J21 -> 3414125.4 | L21: =R21+V21 -> 3960385.6 | N21: =L21-M21 -> 3960385.6 | R21: =SUM(O21:Q21) -> 0 | S21: 3414125.4 | T21: =E21-X21 -> 0 | U21: =F21-Y21 -> 546260.19 | V21: =SUM(S21:U21) -> 3960385.6 | Z21: =SUM(W21:Y21) -> 0 | AA21: 10412714 | AB21: TOP - Sin aclaracion | AC21: =O21+S21+W21 -> 3414125.4 | AD21: =R21+V21+Z21 -> 3960385.6 | AE21: =G21-AD21 -> -0.144361 | AF21: =D21-S21 -> 0 | AG21: Revisión | AH21: 4 | AI21: 8 | AJ21: 08 contactos 29 ene: Agenda de reunion via TEAMs 03 feb: reunion via TEAMS donde se deja claro que el tiempo estimado para NS2025 no se mueve. 04 feb: Proveedor indica que la metodologia de liquidacion presenta diferencias.Se solicita compartir el detalle. 10 feb : Proveedor envia detalle 18-feb-2026 se aclaró con proveedor la metodología del calculo y se solicitó enviar evidencias. 25 feb: Se envia correo al Proveedor solicitando la revisión e informando que debemos cerrar en febrero 2026. 27 feb 2026: El proveedor envia correo informando que esta revisando que le demos al finalizar la próxima semana 27 feb 2026: Auditoria envia correo solicitando nos compartan las revisiones que ya tengan listas, dado que se otorgo una prorroga al 04 de marzo para cerrar. | AK21: CON CONTACTO | AL21: PDTE POR PROVEEDOR | AM21: Yessenia | AS21: 46051 | AU21: 46056 | AV21: 29 ene 2026: el proveedor envia correo informando que esta revisando el detalle y requiere una plazo de 30 dias. Auditoria envia respuesta informando que no es posible ampliar el plazo dado que es un proceso a nivel institucional, no obstante estamos en disposición de apoyar en cualquier inquietud, duda o información adicional.//03 feb reunión con Proveedor se informo que el plazo no se puede extender y quedaron de enviar soportes en la tarde/ | AW21: Casos abiertos( En proceso) | AY21: SI | BA21: Se acercó el proveedor con Andrea solicitando el detalle correspondiente. | BB21: =VLOOKUP(B21,contactos!$A$1:$D$484,4,FALSE) -> irais.quiroga@softys.com
B22: 44040 | C22: LA MADRILENA, S.A. | D22: 2578675.1 | E22: 692321.96 | F22: 523359.53 | G22: 3794356.6 | H22: 0 | I22: =O22+S22 -> 359743.56 | K22: =I22-J22 -> 359743.56 | L22: =R22+V22 -> 532146.53 | N22: =L22-M22 -> 532146.53 | R22: =SUM(O22:Q22) -> 0 | S22: 359743.56 | T22: 99003.45 | U22: 73399.52 | V22: =SUM(S22:U22) -> 532146.53 | W22: 2218931.6 | X22: 593318.51 | Y22: 449960.01 | Z22: =SUM(W22:Y22) -> 3262210.1 | AA22: 3854818.9 | AB22: TOP - Sin aclaracion | AC22: =O22+S22+W22 -> 2578675.1 | AD22: =R22+V22+Z22 -> 3794356.6 | AE22: =G22-AD22 -> -0.010000004 | AG22: Revisión | AH22: 4 | AI22: 8 | AJ22: Se envìo correo el 20-feb-26 nitificando el resultado despues de realizar la revisión de la inforamación recibida,se solicto soportes del saldo pendiente S informa al proveedor el importe pendiente de soportes con el resultado final del analisis segun información recibida, se obtienes respuesta de su parte confirmando la información recibida | AK22: CON CONTACTO | AL22: PDTE POR PROVEEDOR | AM22: Olfi | AS22: 46050 | AT22: Si | AV22: Se le manda correo al proveedor, informandole sobre la auditoria del 2025 Se revisa soportes recibidos los cuales no son procedentes, se soliciat soportes que validen el archivo adjunto y se vuelve a enviar la información Proveedor envia estado de cuenta donde se visualizan los pedidos con pagos aplicados de lo que se reclaman, se realiza cruce de archivo de salida con soporte y se descarga el resultado de SAP para cotejar la información | AY22: X | BB22: =VLOOKUP(B22,contactos!$A$1:$D$484,4,FALSE) -> mrgarciac@bepensa.com
B23: 54569 | C23: FERRERO DE MEXICO SA DE CV | D23: 3454984.1 | E23: 266374.18 | F23: 0 | G23: 3721358.3 | H23: 0 | I23: =O23+S23 -> 3454984.1 | K23: =I23-J23 -> 3454984.1 | L23: =R23+V23 -> 3721358.3 | N23: =L23-M23 -> 3721358.3 | R23: =SUM(O23:Q23) -> 0 | S23: 3454984.1 | T23: =E23-X23 -> 266374.18 | U23: =F23-Y23 -> 0 | V23: =SUM(S23:U23) -> 3721358.3 | Z23: =SUM(W23:Y23) -> 0 | AA23: 9146362.9 | AB23: TOP - Sin aclaracion | AC23: =O23+S23+W23 -> 3454984.1 | AD23: =R23+V23+Z23 -> 3721358.3 | AE23: =G23-AD23 -> -0.034031139 | AF23: =D23-S23 -> 0 | AG23: Revisión | AH23: 4 | AI23: 2 | AJ23: 05 de marzo - se envia correo de seguimiento al proveedor, solicitando respuesta, e informado que de no recibir respuesta se aplicará el cargo 24 de febrero - se envia al proveedor detalle del importe publicado 20 de febrero Carmen de aclaraciones solicita nos acerquemos con proveedor para compartir detalle de pedidos, se manda información a proveedor información el 24 de febrero | AK23: CON CONTACTO | AL23: PDTE POR AUDITORIA | AM23: Marcela | AP23: 12 | AR23: 46076 | AS23: 46050 | AV23: 28 de enero: Se envía correo con información de detalle de ns. 23 de febereo 2026: proveedor revisa con depto. de servicio a proveedores algunas aclaraciones y solicitó detalle del cargo publicado e ingreso el 19 de febrero folios de aclaración. | BB23: =VLOOKUP(B23,contactos!$A$1:$D$484,4,FALSE) -> danielrodrigo.alonso@ferrero.com
B24: 17921 | C24: PRODUCTOS INTERNACIONALES MABE S.A. | D24: 3189882.4 | E24: 0 | F24: 510061.55 | G24: 3699944 | H24: 1438808 | I24: =O24+S24 -> 3189882.4 | K24: =I24-J24 -> 3189882.4 | L24: =R24+V24 -> 3699944 | N24: =L24-M24 -> 3699944 | R24: =SUM(O24:Q24) -> 0 | S24: 3189882.4 | T24: =E24-X24 -> 0 | U24: =F24-Y24 -> 510061.55 | V24: =SUM(S24:U24) -> 3699944 | Z24: =SUM(W24:Y24) -> 0 | AA24: 7893271.1 | AB24: TOP - Sin aclaracion | AC24: =O24+S24+W24 -> 3189882.4 | AD24: =R24+V24+Z24 -> 3699944 | AE24: =G24-AD24 -> 0.055542002 | AF24: =D24-S24 -> 0 | AG24: Revisión | AH24: 4 | AI24: 8 | AJ24: 08 contactos 29 ene: Agenda de reunion via TEAMs 03 feb: reunion via TEAMS donde se deja claro que el tiempo estimado para NS2025 no se mueve. 04 feb: Proveedor indica que la metodologia de liquidacion presenta diferencias.Se solicita compartir el detalle. 10 feb : Proveedor envia detalle 18-feb-2026 se aclaró con proveedor la metodología del calculo y se solicitó enviar evidencias. 25 feb: Se envia correo al Proveedor solicitando la revisión e informando que debemos cerrar en febrero 2026. 27 feb 2026: El proveedor envia correo informando que esta revisando que le demos al finalizar la próxima semana 27 feb 2026: Auditoria envia correo solicitando nos compartan las revisiones que ya tengan listas, dado que se otorgo una prorroga al 04 de marzo para cerrar. | AK24: CON CONTACTO | AL24: PDTE POR PROVEEDOR | AM24: Sareé | AS24: 46050 | AV24: Se le manda correo al proveedor, informandole sobre la auditoria del 2025// 29 ene 2026: el proveedor envia correo informando que esta revisando el detalle y requiere una plazo de 30 dias. Auditoria envia respuesta informando que no es posible ampliar el plazo dado que es un proceso a nivel institucional, no obstante estamos en disposición de apoyar en cualquier inquietud, duda o información adicional.//03 feb reunión con Proveedor se informo que el plazo no se puede extender y quedaron de enviar soportes en la tarde./04 feb : el proveedor envia correo informando que presenta diferencia en la metodologia y que tiene un valor de $868k de ordenes no canceladas y $263K cantidad cancelada menor a la que se reclama. El proveedor solicita el detalle que indique lo que no se entrego. Auditoria envia el archivo de NS ene- ago 2025 de NS donde se detalla por OC la penalizacion y se solicita coloque una columna donde marque las incidencias y otra columna donde realice el calculo segun su metodologia. | AW24: Casos abiertos( En proceso) | AY24: SI | BB24: =VLOOKUP(B24,contactos!$A$1:$D$484,4,FALSE) -> javierhernando.rodriguez@softys.com
B25: 9381 | C25: CHURCH & DWIGHT,S. DE R.L. DE C.V. | D25: 2846318.2 | E25: 0 | F25: 454431.78 | G25: 3300750 | H25: 3300750 | I25: =O25+S25 -> 2846318.2 | K25: =I25-J25 -> 2846318.2 | L25: =R25+V25 -> 3300750 | N25: =L25-M25 -> 3300750 | R25: =SUM(O25:Q25) -> 0 | S25: 2846318.2 | T25: =E25-X25 -> 0 | U25: =F25-Y25 -> 454431.78 | V25: =SUM(S25:U25) -> 3300750 | Z25: =SUM(W25:Y25) -> 0 | AA25: 5586012.1 | AB25: TOP - Aclaracion | AC25: =O25+S25+W25 -> 2846318.2 | AD25: =R25+V25+Z25 -> 3300750 | AE25: =G25-AD25 -> 0.046534983 | AF25: =D25-S25 -> 0 | AG25: Aplicar | AH25: 4 | AI25: 3 | AJ25: 29 ene: Agenda de reunion via TEAMs | AK25: CON CONTACTO | AL25: PDTE POR PROVEEDOR | AM25: Francisco | AR25: 46044 | AS25: 46044 | AV25: Proveedor se acercò a revisar la Auditoria 20-24 y solicitar lo que respecta al 2025, se encuentra en validaciòn. 20feb2026 Lo esta haciendo a nivel pedido. | AY25: X | BA25: Proveedor se acercò a revisar la Auditoria 20-24 y solicitar lo que respecta al 2025, se encuentra en validaciòn | BB25: =VLOOKUP(B25,contactos!$A$1:$D$484,4,FALSE) -> jesus.vidales@churchdwight.com
B26: 24489 | C26: REGALOS SIGLO XXI | D26: 2734026.4 | E26: 0 | F26: 437444.47 | G26: 3171470.8 | H26: 3171470.9 | I26: =O26+S26 -> 2734026.4 | K26: =I26-J26 -> 2734026.4 | L26: =R26+V26 -> 3171470.9 | N26: =L26-M26 -> 3171470.9 | R26: =SUM(O26:Q26) -> 0 | S26: 2734026.4 | T26: =E26-X26 -> 0 | U26: =F26-Y26 -> 437444.47 | V26: =SUM(S26:U26) -> 3171470.9 | Z26: =SUM(W26:Y26) -> 0 | AA26: 2280092.9 | AB26: TOP - Sin aclaracion | AC26: =O26+S26+W26 -> 2734026.4 | AD26: =R26+V26+Z26 -> 3171470.9 | AE26: =G26-AD26 -> -0.11107753 | AF26: =D26-S26 -> 0 | AG26: Aplicar | AH26: 4 | AI26: 4 | AJ26: 03 feb: reunion via TEAMS donde se deja claro que el tiempo estimado para NS2025 no se mueve. | AK26: CON CONTACTO | AL26: SIN ACLARACION | AM26: Raul | AS26: 46050 | AV26: Se le manda correo al proveedor, informandole sobre la auditoria del 2025 | BB26: =VLOOKUP(B26,contactos!$A$1:$D$484,4,FALSE) -> nayellivl@regalossigloxxi.com.mx
B27: 71217 | C27: EDGEWELL PERSONAL CARE MEXICO | D27: 2714666.1 | E27: 0 | F27: 430920.01 | G27: 3145586 | H27: 0 | I27: =O27+S27 -> 2714666.1 | K27: =I27-J27 -> 2714666.1 | L27: =R27+V27 -> 3145586.1 | N27: =L27-M27 -> 3145586.1 | O27: =D27 -> 2714666.1 | Q27: =F27 -> 430920.01 | R27: =SUM(O27:Q27) -> 3145586.1 | S27: 0 | T27: =E27-X27 -> 0 | U27: 0 | V27: =SUM(S27:U27) -> 0 | Z27: =SUM(W27:Y27) -> 0 | AA27: 5458542 | AB27: TOP - Aclaracion | AC27: =O27+S27+W27 -> 2714666.1 | AD27: =R27+V27+Z27 -> 3145586.1 | AE27: =G27-AD27 -> -0.090790675 | AF27: =D27-S27 -> 2714666.1 | AG27: Aplicar | AH27: 4 | AI27: 4 | AJ27: 06 Marzo. Proveedor indica no cuenta con dudas respecto al cargo de la Auditoria por NS 2025. | AK27: CON CONTACTO | AL27: PDTE POR PROVEEDOR | AM27: Mario | AR27: 46048 | AS27: 46048 | AV27: Se tuvo reuniòn con Proveedor para revisar la parte del 20-24 y se presentò lo del 2025, se encuentran en proceso de descarga de los pedidos penalziados. | AY27: X | BA27: Se tuvo reuniòn con Proveedor para revisar la parte del 20-24 y se presentò lo del 2025, se encuentran en proceso de descarga de los pedidos penalziados. | BB27: =VLOOKUP(B27,contactos!$A$1:$D$484,4,FALSE) -> mauriciorene.perez@edgewell.com
B28: 80622 | C28: 3M MEXICO SA DE CV | D28: 2556718.5 | E28: 0 | F28: 409074.99 | G28: 2965793.5 | H28: 2310641.6 | I28: =O28+S28 -> 1991932.4 | K28: =I28-J28 -> 1991932.4 | L28: =R28+V28 -> 2310641.6 | N28: =L28-M28 -> 2310641.6 | O28: =R28/1.16 -> 1991932.4 | Q28: =R28-O28 -> 318709.19 | R28: 2310641.6 | S28: 0 | T28: =E28-X28 -> 0 | U28: 0 | V28: =SUM(S28:U28) -> 0 | W28: 564786.06 | Y28: =W28*16% -> 90365.77 | Z28: =SUM(W28:Y28) -> 655151.83 | AA28: 6887053.2 | AB28: TOP - Sin aclaracion | AC28: =O28+S28+W28 -> 2556718.5 | AD28: =R28+V28+Z28 -> 2965793.5 | AE28: =G28-AD28 -> 0.02845608 | AF28: =D28-S28 -> 2556718.5 | AG28: Revisión | AH28: 4 | AI28: 0 | AJ28: Proveedor envía soporte de lo no procedente y se confirma por parte de la Auditoria el resultado aceptaod. | AK28: CON CONTACTO | AL28: PDTE POR AUDITORIA | AM28: Perla | AN28: 2362760 | AO28: EL PEDIDO FUE CANCELADO EN TIEMPO, NO PROCEDE | AP28: 4 | AR28: 46058 | AS28: 46051 | AV28: EN validaciòn de soporte | BB28: =VLOOKUP(B28,contactos!$A$1:$D$484,4,FALSE) -> aespinosacruz@mmm.com
B29: 7875 | C29: LINGERIX SA DE CV | D29: 2514428.2 | E29: 0 | F29: 402308.46 | G29: 2916736.6 | H29: 1259442.8 | I29: =O29+S29 -> 2514428.2 | K29: =I29-J29 -> 2514428.2 | L29: =R29+V29 -> 2916736.6 | N29: =L29-M29 -> 2916736.6 | R29: =SUM(O29:Q29) -> 0 | S29: 2514428.2 | T29: =E29-X29 -> 0 | U29: =F29-Y29 -> 402308.46 | V29: =SUM(S29:U29) -> 2916736.6 | Z29: =SUM(W29:Y29) -> 0 | AA29: 1864880.4 | AB29: TOP - Sin aclaracion | AC29: =O29+S29+W29 -> 2514428.2 | AD29: =R29+V29+Z29 -> 2916736.6 | AE29: =G29-AD29 -> -0.032818869 | AF29: =D29-S29 -> 0 | AG29: Aplicar | AH29: 4 | AI29: 1 | AJ29: 18-feb-2026 se aclaró con proveedor la metodología del calculo y se solicitó enviar evidencias. | AK29: CON CONTACTO | AL29: SIN ACLARACION | AM29: Yessica | AS29: 46050 | AT29: 29-01-2026 | AV29: Se envia Manual y detalle NS 2025 | BA29: PROVEEDOR CONFIRMA RECIBIDO Y SOLICITÓ AMPLIACION DE PLAZO | BB29: =VLOOKUP(B29,contactos!$A$1:$D$484,4,FALSE) -> favalle@assatex.com
B30: 313387 | C30: NATURASOL S.A. DE C.V. | D30: 2678050.9 | E30: 145825.82 | F30: 0 | G30: 2823876.7 | H30: 2823876.7 | I30: =O30+S30 -> 2678050.9 | K30: =I30-J30 -> 2678050.9 | L30: =R30+V30 -> 2823876.7 | N30: =L30-M30 -> 2823876.7 | R30: =SUM(O30:Q30) -> 0 | S30: 2678050.9 | T30: =E30-X30 -> 145825.82 | U30: =F30-Y30 -> 0 | V30: =SUM(S30:U30) -> 2823876.7 | Z30: =SUM(W30:Y30) -> 0 | AA30: 7033118.2 | AB30: TOP - Sin aclaracion | AC30: =O30+S30+W30 -> 2678050.9 | AD30: =R30+V30+Z30 -> 2823876.7 | AE30: =G30-AD30 -> -0.00036524329 | AF30: =D30-S30 -> 0 | AG30: Aplicar | AH30: 4 | AI30: 1 | AJ30: 25 feb: Se envia correo al Proveedor solicitando la revisión e informando que debemos cerrar en febrero 2026. | AK30: CON CONTACTO | AL30: SIN ACLARACION | AM30: Sareé | AS30: 46050 | AV30: Se le manda correo al proveedor, informandole sobre la auditoria del 2025 | BB30: =VLOOKUP(B30,contactos!$A$1:$D$484,4,FALSE) -> montserrat.buendia@naturasol.com.mx
B31: 308421 | C31: PEDRO DOMECQ SA DE CV | D31: 1612446.7 | E31: 790165.74 | F31: 384417.99 | G31: 2787030.5 | H31: 2787030.5 | I31: =O31+S31 -> 175079.38 | J31: 0 | K31: =I31-J31 -> 175079.38 | L31: =R31+V31 -> 293132.01 | M31: 0 | N31: =L31-M31 -> 293132.01 | R31: =SUM(O31:Q31) -> 0 | S31: =D31-W31 -> 175079.38 | T31: =E31-X31 -> 77620.624 | U31: =F31-Y31 -> 40432.001 | V31: =SUM(S31:U31) -> 293132.01 | W31: 1437367.3 | X31: 712545.12 | Y31: 343985.99 | Z31: =SUM(W31:Y31) -> 2493898.4 | AA31: 1083868.5 | AB31: TOP - Sin aclaracion | AC31: =O31+S31+W31 -> 1612446.7 | AD31: =R31+V31+Z31 -> 2787030.4 | AE31: =G31-AD31 -> 0.11877878 | AF31: =D31-S31 -> 1437367.3 | AG31: Aplicar | AH31: 4 | AI31: 1 | AJ31: 27 feb 2026: El proveedor envia correo informando que esta revisando que le demos al finalizar la próxima semana | AK31: CON CONTACTO | AL31: SIN ACLARACION | AM31: Belem | BB31: =VLOOKUP(B31,contactos!$A$1:$D$484,4,FALSE) -> jamador@pedrodomecq.com
B32: 82511 | C32: HENKEL CAPITAL SA DE CV | D32: 2380059.3 | E32: 0 | F32: 380809.51 | G32: 2760868.8 | H32: 2760868.8 | I32: =O32+S32 -> 2380059.3 | K32: =I32-J32 -> 2380059.3 | L32: =R32+V32 -> 2760868.8 | N32: =L32-M32 -> 2760868.8 | R32: =SUM(O32:Q32) -> 0 | S32: 2380059.3 | T32: =E32-X32 -> 0 | U32: =F32-Y32 -> 380809.51 | V32: =SUM(S32:U32) -> 2760868.8 | Z32: =SUM(W32:Y32) -> 0 | AA32: 8524572 | AB32: TOP - Sin aclaracion | AC32: =O32+S32+W32 -> 2380059.3 | AD32: =R32+V32+Z32 -> 2760868.8 | AE32: =G32-AD32 -> -0.01879867 | AF32: =D32-S32 -> 0 | AG32: Aplicar | AH32: 4 | AI32: 1 | AJ32: 27 feb 2026: Auditoria envia correo solicitando nos compartan las revisiones que ya tengan listas, dado que se otorgo una prorroga al 04 de marzo para cerrar. | AK32: CON CONTACTO | AL32: SIN ACLARACION | AM32: raul | AS32: 46050 | AV32: Se le manda correo al proveedor, informandole sobre la auditoria del 2025 | BB32: =VLOOKUP(B32,contactos!$A$1:$D$484,4,FALSE) -> #N/A
B33: 21943 | C33: HENKEL CAPITAL SA DE CV | D33: 2292934.1 | E33: 0 | F33: 366869.46 | G33: 2659803.7 | H33: 2659803.7 | I33: =O33+S33 -> 2292934.1 | K33: =I33-J33 -> 2292934.1 | L33: =R33+V33 -> 2659803.6 | N33: =L33-M33 -> 2659803.6 | R33: =SUM(O33:Q33) -> 0 | S33: 2292934.1 | T33: =E33-X33 -> 0 | U33: =F33-Y33 -> 366869.46 | V33: =SUM(S33:U33) -> 2659803.6 | Z33: =SUM(W33:Y33) -> 0 | AA33: 17985209 | AB33: TOP - Sin aclaracion | AC33: =O33+S33+W33 -> 2292934.1 | AD33: =R33+V33+Z33 -> 2659803.6 | AE33: =G33-AD33 -> 0.059903516 | AF33: =D33-S33 -> 0 | AG33: Aplicar | AH33: 4 | AI33: 1 | AJ33: 1 contacto se le informa de la auditoria | AK33: CON CONTACTO | AL33: SIN ACLARACION | AM33: Raul | AS33: 46050 | AV33: Se le manda correo al proveedor, informandole sobre la auditoria del 2025 | BB33: =VLOOKUP(B33,contactos!$A$1:$D$484,4,FALSE) -> loreto.zalapa@henkel.com
B34: 364 | C34: MARINDUSTRIAS S.A. DE C.V. | D34: 2535880.7 | E34: 0 | F34: 0 | G34: 2535881.1 | H34: 2535880.7 | I34: =O34+S34 -> 2535880.7 | K34: =I34-J34 -> 2535880.7 | L34: =R34+V34 -> 2535880.7 | N34: =L34-M34 -> 2535880.7 | R34: =SUM(O34:Q34) -> 0 | S34: 2535880.7 | T34: =E34-X34 -> 0 | U34: =F34-Y34 -> 0 | V34: =SUM(S34:U34) -> 2535880.7 | Z34: =SUM(W34:Y34) -> 0 | AA34: 18199055 | AB34: TOP - Sin aclaracion | AC34: =O34+S34+W34 -> 2535880.7 | AD34: =R34+V34+Z34 -> 2535880.7 | AE34: =G34-AD34 -> 0.37418238 | AF34: =D34-S34 -> 0 | AG34: Aplicar | AH34: 4 | AI34: 1 | AJ34: 6 - feb -2026, Sin respuesta al dia hoy, se le solicito los soportes de cancelacion (1 correos de Seguimiento) | AK34: CON CONTACTO | AL34: PDTE POR PROVEEDOR | AM34: Yessenia | AN34: 260797.11 | AO34: REEMBOLOS DEBIDO A QUE EL PEDIDO NUCA SE VIO REFLEJADO | AP34: 1 | AR34: 46059 | AV34: compartió soportes que no justifican la improcedencia, se le informo sus soportes no son validos. Sin respuesta. | BB34: =VLOOKUP(B34,contactos!$A$1:$D$484,4,FALSE) -> hperalta@grupomar.mx
B35: 11914 | C35: HALEON CONSUMER HEALTHCARE MEXICO | D35: 2177336.9 | E35: 0 | F35: 348373.9 | G35: 2525710.9 | H35: 0 | I35: =O35+S35 -> 1721832.9 | J35: 0 | K35: =I35-J35 -> 1721832.9 | L35: =R35+V35 -> 2108224.7 | M35: 0 | N35: =L35-M35 -> 2108224.7 | O35: 1610934.5 | Q35: 257749.52 | R35: =SUM(O35:Q35) -> 1868684 | S35: =D35-(O35+W35) -> 110898.44 | T35: =E35-(P35+X35) -> 0 | U35: =G35-(R35+Z35) -> 128642.3 | V35: =SUM(S35:U35) -> 239540.74 | W35: 455503.97 | X35: 0 | Y35: 72880.64 | Z35: =SUM(W35:Y35) -> 528384.61 | AA35: 1195941.8 | AB35: TOP - Sin aclaracion | AC35: =O35+S35+W35 -> 2177336.9 | AD35: =R35+V35+Z35 -> 2636609.3 | AE35: =G35-AD35 -> -110898.44 | AF35: =D35-S35 -> 2066438.4 | AG35: Revisión | AH35: 4 | AI35: 5 | AJ35: Reunión con proveedor 24 feb 26, menciona saldo procedente, y confirmación de soportes que amparan improcedencia de 110K antes de imp, se dieron 3 seguimiento, una reunión presencial y una sesión | AK35: CON CONTACTO | AL35: PDTE POR AUDITORIA | AM35: Luis | AS35: 46050 | AV35: Se envía correo con información de detalle de ns | BB35: =VLOOKUP(B35,contactos!$A$1:$D$484,4,FALSE) -> mateo.x.mendoza@haleon.com
B36: 51698 | C36: BARDAHL DE MEXICO S. A. DE C. V. | D36: 2017199.9 | E36: 0 | F36: 322752 | G36: 2339951.9 | H36: 1207074.1 | I36: =O36+S36 -> 2017199.9 | K36: =I36-J36 -> 2017199.9 | L36: =R36+V36 -> 2339951.9 | N36: =L36-M36 -> 2339951.9 | R36: =SUM(O36:Q36) -> 0 | S36: 2017199.9 | T36: =E36-X36 -> 0 | U36: =F36-Y36 -> 322752 | V36: =SUM(S36:U36) -> 2339951.9 | Z36: =SUM(W36:Y36) -> 0 | AA36: 1820258.9 | AB36: TOP - Sin aclaracion | AC36: =O36+S36+W36 -> 2017199.9 | AD36: =R36+V36+Z36 -> 2339951.9 | AE36: =G36-AD36 -> 0.04752231 | AF36: =D36-S36 -> 0 | AG36: Aplicar | AH36: 4 | AI36: 1 | AJ36: Proveedor no mandas soportes de improcedencia se tuvo un contacto en correo el 28 de enero en el que se compartió la información de pedidos, en seguimiento del 2020-2024 proveedor hace una llamada el 20 de febrero pero no menciona nada con relación al ejercicio 2025 | AK36: CON CONTACTO | AL36: SIN ACLARACION | AM36: Marcela | AS36: 46050 | AV36: Se envía correo con información de detalle de ns | BB36: =VLOOKUP(B36,contactos!$A$1:$D$484,4,FALSE) -> francisca.lopez@bardahl.com.mx
B37: 12480 | C37: DETERGENTES Y JABONES SASIL SAPI SA | D37: 1963610.8 | E37: 0 | F37: 314177.73 | G37: 2277788.4 | H37: 1055297.2 | I37: =O37+S37 -> 1963610.8 | K37: =I37-J37 -> 1963610.8 | L37: =R37+V37 -> 2277788.5 | N37: =L37-M37 -> 2277788.5 | R37: =SUM(O37:Q37) -> 0 | S37: =+D37 -> 1963610.8 | T37: =E37-X37 -> 0 | U37: =F37-Y37 -> 314177.73 | V37: =SUM(S37:U37) -> 2277788.5 | Z37: =SUM(W37:Y37) -> 0 | AA37: 2552379.4 | AB37: TOP - Aclaracion | AC37: =O37+S37+W37 -> 1963610.8 | AD37: =R37+V37+Z37 -> 2277788.5 | AE37: =G37-AD37 -> -0.094975847 | AF37: =D37-S37 -> 0 | AG37: Aplicar | AH37: 4 | AI37: 5 | AJ37: Se enviò correo el 17-feb-26 indicando que se requiere la autorización del area comercial para desestimar unos pedidos que indican que se realizó una solicitud de configuración | AK37: CON CONTACTO | AL37: PDTE POR PROVEEDOR | AM37: Olfi | AN37: 2277788.4 | AO37: DETALLE DE LOS CARGOS EN EL PORTAL | AR37: 46038 | AS37: 46041 | AT37: Si | AV37: Proveedor solicito detalle y se le hizo llegar Se Indica que es necesario la solicitud de la autorización del area comercial para el tema de configuración de unos pedidos, proveedor tiene un seguimiento de esta solicitud | AW37: Casos abiertos( En proceso) | AY37: X | BA37: Raul Castillo recibio correo en cuenta soriana | BB37: =VLOOKUP(B37,contactos!$A$1:$D$484,4,FALSE) -> EESCAMILLA@SASIL.MX
B38: 11042 | C38: BEBIDAS INTERNACIONALES BEPENSA SA | D38: 1539286 | E38: 407910.77 | F38: 311551.54 | G38: 2258748.2 | H38: 0 | I38: =O38+S38 -> 1467671.4 | K38: =I38-J38 -> 1467671.4 | L38: =R38+V38 -> 2153661 | N38: =L38-M38 -> 2153661 | R38: =SUM(O38:Q38) -> 0 | S38: =D38-W38 -> 1467671.4 | T38: =E38-X38 -> 388932.9 | U38: =F38-Y38 -> 297056.74 | V38: =SUM(S38:U38) -> 2153661 | W38: 71614.62 | X38: 18977.87 | Y38: 14494.8 | Z38: =SUM(W38:Y38) -> 105087.29 | AA38: 1267567.6 | AB38: TOP - Sin aclaracion | AC38: =O38+S38+W38 -> 1539286 | AD38: =R38+V38+Z38 -> 2258748.3 | AE38: =G38-AD38 -> -0.12480254 | AG38: Revisión | AH38: 4 | AI38: 3 | AJ38: En revisión OC restantes | AK38: CON CONTACTO | AL38: PDTE POR PROVEEDOR | AM38: Sareé | AS38: 46050 | AV38: Proveedor envía soporte de OC ya cobradas | BB38: =VLOOKUP(B38,contactos!$A$1:$D$484,4,FALSE) -> dagarciad@bepensa.com
B39: 307988 | C39: 4E GLOBAL SAPI DE CV | D39: 1768456.2 | E39: 0 | F39: 282953 | G39: 2051409.4 | H39: 2051409.2 | I39: =O39+S39 -> 1768456.2 | K39: =I39-J39 -> 1768456.2 | L39: =R39+V39 -> 2051409.2 | N39: =L39-M39 -> 2051409.2 | R39: =SUM(O39:Q39) -> 0 | S39: 1768456.2 | T39: =E39-X39 -> 0 | U39: =F39-Y39 -> 282953 | V39: =SUM(S39:U39) -> 2051409.2 | Z39: =SUM(W39:Y39) -> 0 | AA39: 3579101.2 | AB39: TOP - Sin aclaracion | AC39: =O39+S39+W39 -> 1768456.2 | AD39: =R39+V39+Z39 -> 2051409.2 | AE39: =G39-AD39 -> 0.1417 | AF39: =D39-S39 -> 0 | AG39: Aplicar | AH39: 4 | AI39: 1 | AJ39: 0 | AK39: CON CONTACTO | AL39: SIN ACLARACION | AM39: Yessenia | BB39: =VLOOKUP(B39,contactos!$A$1:$D$484,4,FALSE) -> esilva@4eglobal.com
B40: 319178 | C40: NISSIN FOODS DE MEXICO SA DE CV | D40: 1899275.9 | E40: 0 | F40: 0 | G40: 1899275.9 | H40: 1307819.1 | I40: =O40+S40 -> 1307819.2 | K40: =I40-J40 -> 1307819.2 | L40: =R40+V40 -> 1307819.2 | N40: =L40-M40 -> 1307819.2 | R40: =SUM(O40:Q40) -> 0 | S40: =D40-O40-W40 -> 1307819.2 | T40: =E40-X40-P40 -> 0 | U40: =F40-Y40-Q40 -> 0 | V40: =SUM(S40:U40) -> 1307819.2 | W40: 591456.77 | X40: 0 | Y40: 0 | Z40: =SUM(W40:Y40) -> 591456.77 | AA40: 1312735.7 | AB40: TOP - Aclaracion | AC40: =O40+S40+W40 -> 1899275.9 | AD40: =R40+V40+Z40 -> 1899275.9 | AE40: =G40-AD40 -> -0.028144169 | AG40: Revisión | AH40: 4 | AI40: 4 | AJ40: En revisión OC restantes | AK40: CON CONTACTO | AL40: PDTE POR PROVEEDOR | AM40: Sareé | AR40: 46042 | AS40: 46043 | AV40: Proveedor comparte evidencia de OC ya cobradas por sistema. | AY40: X | BA40: Se contactó con Raúl vía correo solicitando el detalle | BB40: =VLOOKUP(B40,contactos!$A$1:$D$484,4,FALSE) -> CPERAZA@NISSINFOODS.COM.MX
B41: 7410 | C41: PRODUCTOS INTERNACIONALES MABE S.A. | D41: 1677791 | E41: 0 | F41: 220404.51 | G41: 1898195.6 | H41: 181552.84 | I41: =O41+S41 -> 1677791 | K41: =I41-J41 -> 1677791 | L41: =R41+V41 -> 1898195.5 | N41: =L41-M41 -> 1898195.5 | R41: =SUM(O41:Q41) -> 0 | S41: 1677791 | T41: =E41-X41 -> 0 | U41: =F41-Y41 -> 220404.51 | V41: =SUM(S41:U41) -> 1898195.5 | Z41: =SUM(W41:Y41) -> 0 | AA41: 6080952.8 | AB41: TOP - Sin aclaracion | AC41: =O41+S41+W41 -> 1677791 | AD41: =R41+V41+Z41 -> 1898195.5 | AE41: =G41-AD41 -> 0.071853234 | AF41: =D41-S41 -> 0 | AG41: Revisión | AH41: 4 | AI41: 8 | AJ41: 08 contactos 29 ene: Agenda de reunion via TEAMs 03 feb: reunion via TEAMS donde se deja claro que el tiempo estimado para NS2025 no se mueve. 04 feb: Proveedor indica que la metodologia de liquidacion presenta diferencias.Se solicita compartir el detalle. 10 feb : Proveedor envia detalle 18-feb-2026 se aclaró con proveedor la metodología del calculo y se solicitó enviar evidencias. 25 feb: Se envia correo al Proveedor solicitando la revisión e informando que debemos cerrar en febrero 2026. 27 feb 2026: El proveedor envia correo informando que esta revisando que le demos al finalizar la próxima semana 27 feb 2026: Auditoria envia correo solicitando nos compartan las revisiones que ya tengan listas, dado que se otorgo una prorroga al 04 de marzo para cerrar. | AK41: CON CONTACTO | AL41: PDTE POR PROVEEDOR | AM41: Andrea | AS41: 46050 | AV41: Se envía correo informando que el comunicado de cargo NS correspondiente al periodo de enero a agosto de 2025 ya se encuentra publicado en el Portal. El detalle del mismo también está disponible desglosado en el Portal. Se adjunta manual de visualizacion de Cargos.// 29 ene 2026: el proveedor envia correo informando que esta revisando el detalle y requiere una plazo de 30 dias. Auditoria envia respuesta informando que no es posible ampliar el plazo dado que es un proceso a nivel institucional, no obstante estamos en disposición de apoyar en cualquier inquietud, duda o información adicional.//03 feb reunión con Proveedor se informo que el plazo no se puede extender y quedaron de enviar soportes en la tarde./04 feb : el proveedor envia correo informando que presenta diferencia en la metodologia y que tiene un valor de $868k de ordenes no canceladas y $263K cantidad cancelada menor a la que se reclama. El proveedor solicita el detalle que indique lo que no se entrego. Auditoria envia el archivo de NS ene- ago 2025 de NS donde se detalla por OC la penalizacion y se solicita coloque una columna donde marque las incidencias y otra columna donde realice el calculo segun su metodologia. | AW41: Casos abiertos( En proceso) | AY41: SI | BB41: =VLOOKUP(B41,contactos!$A$1:$D$484,4,FALSE) -> javierhernando.rodriguez@softys.com
...

Sheet Resumen
B3: Count Proveedor | C3: Publicado en Portal | D3: Aceptado (antes_impto) | E3: Pendiente (antes_impto) | F3: Soportado (no procede antes_impto) | G3: Penalizacion_con Imptos | H3: Aceptado_con Imptos | I3: Pendiente_con Imptos | J3: Soportado_con Imptos
A4: CON CONTACTO | B4: 117 | C4: 3.2774067e+08 | D4: 48455381 | E4: 2.5010905e+08 | F4: 29176248 | G4: 3.6878422e+08 | H4: 54787016 | I4: 2.8010932e+08 | J4: 33887877
A5: SIN CONTACTO
A6: SIN ACLARACION | B6: 315 | C6: 42055334 | E6: 42055334 | G6: 47129266 | H6: 0 | I6: 47129265 | J6: 0
A7: Grand Total | B7: 432 | C7: 3.6979601e+08 | D7: 48455381 | E7: 2.9216438e+08 | F7: 29176248 | G7: 4.1591348e+08 | H7: 54787016 | I7: 3.2723859e+08 | J7: 33887877

Sheet Detalle Cargos 24Mzo26
E1: =SUBTOTAL(9,E3:E1621) -> 1.936889e+08
A2: Document Number | B2: Account | C2: Document Type | D2: Document Date | E2: Amount in local currency | F2: Local Currency | G2: Clearing Document | H2: aplicado | I2: Text | J2: Payment Block | K2: Clearing date | L2: Net due date | M2: Reference | N2: Reference Key 3 | O2: Company Code | P2: Reference Key 2 | Q2: Reference Key 1 | R2: Payment Method | S2: Assignment | T2: User name
A3: 5100421550 | B3: 137 | C3: RA | D3: 46035 | E3: 293072.27 | F3: MXN | G3: 1500030420 | H3: aplicado | I3: AUD PRGX NIVEL SERVICIO 2025 | K3: 46090 | L3: 46035 | M3: 12025 | N3: ZD33 | O3: 2001 | S3: 514375 | T3: BOT_CARGOPRO
A4: 5100421551 | B4: 137 | C4: RA | D4: 46035 | E4: 104772.03 | F4: MXN | G4: 1500030420 | H4: aplicado | I4: AUD PRGX NIVEL SERVICIO 2025 | K4: 46090 | L4: 46035 | M4: 22025 | N4: ZD33 | O4: 2001 | S4: 514375 | T4: BOT_CARGOPRO
A5: 5100421552 | B5: 137 | C5: RA | D5: 46035 | E5: 74217.98 | F5: MXN | G5: 1500030420 | H5: aplicado | I5: AUD PRGX NIVEL SERVICIO 2025 | K5: 46090 | L5: 46035 | M5: 42025 | N5: ZD33 | O5: 2001 | S5: 514375 | T5: BOT_CARGOPRO
A6: 5100421553 | B6: 137 | C6: RA | D6: 46035 | E6: 467518.42 | F6: MXN | G6: 1500030420 | H6: aplicado | I6: AUD PRGX NIVEL SERVICIO 2025 | K6: 46090 | L6: 46035 | M6: 52025 | N6: ZD33 | O6: 2001 | S6: 514375 | T6: BOT_CARGOPRO
A7: 5100421554 | B7: 137 | C7: RA | D7: 46035 | E7: 156092.31 | F7: MXN | G7: 1500030420 | H7: aplicado | I7: AUD PRGX NIVEL SERVICIO 2025 | K7: 46090 | L7: 46035 | M7: 62025 | N7: ZD33 | O7: 2001 | S7: 514375 | T7: BOT_CARGOPRO
A8: 5100421555 | B8: 137 | C8: RA | D8: 46035 | E8: 260718.21 | F8: MXN | G8: 1500030420 | H8: aplicado | I8: AUD PRGX NIVEL SERVICIO 2025 | K8: 46090 | L8: 46035 | M8: 72025 | N8: ZD33 | O8: 2001 | S8: 514375 | T8: BOT_CARGOPRO
A9: 5100421556 | B9: 137 | C9: RA | D9: 46035 | E9: 1158.06 | F9: MXN | G9: 1500030420 | H9: aplicado | I9: AUD PRGX NIVEL SERVICIO 2025 | K9: 46090 | L9: 46035 | M9: 82025 | N9: ZD33 | O9: 2001 | S9: 514375 | T9: BOT_CARGOPRO
A10: 5100421557 | B10: 137 | C10: RA | D10: 46035 | E10: 877.73 | F10: MXN | G10: 1500030420 | H10: aplicado | I10: AUD PRGX NIVEL SERVICIO 2025 | K10: 46090 | L10: 46035 | M10: 92025 | N10: ZD33 | O10: 2001 | S10: 514375 | T10: BOT_CARGOPRO
A11: 5100422412 | B11: 3137 | C11: RA | D11: 46035 | E11: 2463.99 | F11: MXN | G11: 1500038737 | H11: aplicado | I11: AUD PRGX NIVEL SERVICIO 2025 | K11: 46069 | L11: 46035 | M11: 32025 | N11: ZD33 | O11: 2001 | S11: 0 | T11: BOT_CARGOPRO
A12: 5100422417 | B12: 3137 | C12: RA | D12: 46035 | E12: 168978.54 | F12: MXN | G12: 1500038737 | H12: aplicado | I12: AUD PRGX NIVEL SERVICIO 2025 | K12: 46069 | L12: 46035 | M12: 92025 | N12: ZD33 | O12: 2001 | S12: 0 | T12: BOT_CARGOPRO
A13: 5100422419 | B13: 3137 | C13: RA | D13: 46035 | E13: 31525.22 | F13: MXN | G13: 1500038737 | H13: aplicado | I13: AUD PRGX NIVEL SERVICIO 2025 | K13: 46069 | L13: 46035 | M13: 102025 | N13: ZD33 | O13: 2001 | S13: 0 | T13: BOT_CARGOPRO
A14: 5100422411 | B14: 3137 | C14: RA | D14: 46035 | E14: 53531.7 | F14: MXN | G14: 1500038737 | H14: aplicado | I14: AUD PRGX NIVEL SERVICIO 2025 | K14: 46069 | L14: 46035 | M14: 22025 | N14: ZD33 | O14: 2001 | S14: 514152 | T14: BOT_CARGOPRO
... A19: 5100422418 | B19: 3137 | C19: RA | D19: 46035 | E19: 12545.4 | F19: MXN | G19: 1500038737 | H19: aplicado | I19: AUD PRGX NIVEL SERVICIO 2025 | K19: 46069 | L19: 46035 | M19: 92025 | N19: ZD33 | O19: 2001 | S19: 514152 | T19: BOT_CARGOPRO
A20: 5100423147 | B20: 4077 | C20: RA | D20: 46035 | E20: 166679.09 | F20: MXN | G20: 1500090927 | H20: aplicado | I20: AUD PRGX NIVEL SERVICIO 2025 | J20: 8 | K20: 46072 | L20: 46035 | M20: 12025 | N20: ZD33 | O20: 2001 | S20: PROGRAMACION 2302 | T20: BOT_CARGOPRO
A21: 5100423148 | B21: 4077 | C21: RA | D21: 46035 | E21: 943.61 | F21: MXN | G21: 1500090927 | H21: aplicado | I21: AUD PRGX NIVEL SERVICIO 2025 | J21: 8 | K21: 46072 | L21: 46035 | M21: 22025 | N21: ZD33 | O21: 2001 | S21: PROGRAMACION 2302 | T21: BOT_CARGOPRO
A22: 5100423149 | B22: 4077 | C22: RA | D22: 46035 | E22: 1190734.9 | F22: MXN | G22: 1500090927 | H22: aplicado | I22: AUD PRGX NIVEL SERVICIO 2025 | J22: 8 | K22: 46072 | L22: 46035 | M22: 22025 | N22: ZD33 | O22: 2001 | S22: PROGRAMACION 2302 | T22: BOT_CARGOPRO
A23: 5100423150 | B23: 4077 | C23: RA | D23: 46035 | E23: 9767.24 | F23: MXN | G23: 1500090927 | H23: aplicado | I23: AUD PRGX NIVEL SERVICIO 2025 | J23: 8 | K23: 46072 | L23: 46035 | M23: 32025 | N23: ZD33 | O23: 2001 | S23: PROGRAMACION 2302 | T23: BOT_CARGOPRO
A24: 5100423151 | B24: 4077 | C24: RA | D24: 46035 | E24: 4960880.8 | F24: MXN | G24: 1500090927 | H24: aplicado | I24: AUD PRGX NIVEL SERVICIO 2025 | J24: 8 | K24: 46072 | L24: 46035 | M24: 32025 | N24: ZD33 | O24: 2001 | S24: PROGRAMACION 2302 | T24: BOT_CARGOPRO
A25: 5100423152 | B25: 4077 | C25: RA | D25: 46035 | E25: 1422090.7 | F25: MXN | G25: 1500090927 | H25: aplicado | I25: AUD PRGX NIVEL SERVICIO 2025 | J25: 8 | K25: 46072 | L25: 46035 | M25: 42025 | N25: ZD33 | O25: 2001 | S25: PROGRAMACION 2302 | T25: BOT_CARGOPRO
A26: 5100423153 | B26: 4077 | C26: RA | D26: 46035 | E26: 4803337.5 | F26: MXN | G26: 1500090927 | H26: aplicado | I26: AUD PRGX NIVEL SERVICIO 2025 | J26: 8 | K26: 46072 | L26: 46035 | M26: 52025 | N26: ZD33 | O26: 2001 | S26: PROGRAMACION 2302 | T26: BOT_CARGOPRO
A27: 5100423154 | B27: 4077 | C27: RA | D27: 46035 | E27: 2854759.5 | F27: MXN | G27: 1500090927 | H27: aplicado | I27: AUD PRGX NIVEL SERVICIO 2025 | J27: 8 | K27: 46072 | L27: 46035 | M27: 62025 | N27: ZD33 | O27: 2001 | S27: PROGRAMACION 2302 | T27: BOT_CARGOPRO
A28: 5100423155 | B28: 4077 | C28: RA | D28: 46035 | E28: 1820340.2 | F28: MXN | G28: 1500090927 | H28: aplicado | I28: AUD PRGX NIVEL SERVICIO 2025 | J28: 8 | K28: 46072 | L28: 46035 | M28: 72025 | N28: ZD33 | O28: 2001 | S28: PROGRAMACION 2302 | T28: BOT_CARGOPRO
A29: 5100423156 | B29: 4077 | C29: RA | D29: 46035 | E29: 560361.35 | F29: MXN | G29: 1500090927 | H29: aplicado | I29: AUD PRGX NIVEL SERVICIO 2025 | J29: 8 | K29: 46072 | L29: 46035 | M29: 82025 | N29: ZD33 | O29: 2001 | S29: PROGRAMACION 2302 | T29: BOT_CARGOPRO
A30: 5100423157 | B30: 4077 | C30: RA | D30: 46035 | E30: 53555.81 | F30: MXN | G30: 1500090927 | H30: aplicado | I30: AUD PRGX NIVEL SERVICIO 2025 | J30: 8 | K30: 46072 | L30: 46035 | M30: 82025 | N30: ZD34 | O30: 2001 | S30: PROGRAMACION 2302 | T30: BOT_CARGOPRO
A31: 5100423158 | B31: 4077 | C31: RA | D31: 46035 | E31: 209085.6 | F31: MXN | G31: 1500090927 | H31: aplicado | I31: AUD PRGX NIVEL SERVICIO 2025 | J31: 8 | K31: 46072 | L31: 46035 | M31: 92025 | N31: ZD33 | O31: 2001 | S31: PROGRAMACION 2302 | T31: BOT_CARGOPRO
A32: 5100423356 | B32: 5330 | C32: RA | D32: 46035 | E32: 15146.33 | F32: MXN | G32: 1500034424 | H32: aplicado | I32: AUD PRGX NIVEL SERVICIO 2025 | K32: 46084 | L32: 46035 | M32: 62025 | N32: ZD33 | O32: 2001 | S32: PROGRAMACION 0303 | T32: BOT_CARGOPRO
A33: 5100423357 | B33: 5330 | C33: RA | D33: 46035 | E33: 1093857.5 | F33: MXN | G33: 1500034424 | H33: aplicado | I33: AUD PRGX NIVEL SERVICIO 2025 | K33: 46084 | L33: 46035 | M33: 82025 | N33: ZD33 | O33: 2001 | S33: PROGRAMACION 0303 | T33: BOT_CARGOPRO
A34: 5100423358 | B34: 5330 | C34: RA | D34: 46035 | E34: 6682.01 | F34: MXN | G34: 1500034424 | H34: aplicado | I34: AUD PRGX NIVEL SERVICIO 2025 | K34: 46084 | L34: 46035 | M34: 92025 | N34: ZD33 | O34: 2001 | S34: PROGRAMACION 0303 | T34: BOT_CARGOPRO
A35: 5100423466 | B35: 5766 | C35: RA | D35: 46035 | E35: 107388.26 | F35: MXN | G35: 1500048380 | H35: aplicado | I35: AUD PRGX NIVEL SERVICIO 2025 | K35: 46090 | L35: 46035 | M35: 12025 | N35: ZD33 | O35: 2001 | S35: 515480 | T35: BOT_CARGOPRO
A36: 5100423467 | B36: 5766 | C36: RA | D36: 46035 | E36: 162.82 | F36: MXN | G36: 1500048380 | H36: aplicado | I36: AUD PRGX NIVEL SERVICIO 2025 | K36: 46090 | L36: 46035 | M36: 12025 | N36: ZD33 | O36: 2001 | S36: 515480 | T36: BOT_CARGOPRO
A37: 5100423468 | B37: 5766 | C37: RA | D37: 46035 | E37: 185208.96 | F37: MXN | G37: 1500048380 | H37: aplicado | I37: AUD PRGX NIVEL SERVICIO 2025 | K37: 46090 | L37: 46035 | M37: 32025 | N37: ZD33 | O37: 2001 | S37: 515480 | T37: BOT_CARGOPRO
A38: 5100423469 | B38: 5766 | C38: RA | D38: 46035 | E38: 244057.4 | F38: MXN | G38: 1500048380 | H38: aplicado | I38: AUD PRGX NIVEL SERVICIO 2025 | K38: 46090 | L38: 46035 | M38: 42025 | N38: ZD33 | O38: 2001 | S38: 515480 | T38: BOT_CARGOPRO
A39: 5100423886 | B39: 8593 | C39: RA | D39: 46035 | E39: 29398 | F39: MXN | G39: 1500034317 | H39: aplicado | I39: AUD PRGX NIVEL SERVICIO 2025 | K39: 46104 | L39: 46035 | M39: 12025 | N39: ZD33 | O39: 2001 | S39: PROGRAMACION 2303 | T39: BOT_CARGOPRO
A40: 5100423887 | B40: 8593 | C40: RA | D40: 46035 | E40: 1003621.9 | F40: MXN | G40: 1500034317 | H40: aplicado | I40: AUD PRGX NIVEL SERVICIO 2025 | K40: 46104 | L40: 46035 | M40: 22025 | N40: ZD33 | O40: 2001 | S40: PROGRAMACION 2303 | T40: BOT_CARGOPRO
A41: 5100423888 | B41: 8593 | C41: RA | D41: 46035 | E41: 886194.71 | F41: MXN | G41: 1500034317 | H41: aplicado | I41: AUD PRGX NIVEL SERVICIO 2025 | K41: 46104 | L41: 46035 | M41: 32025 | N41: ZD33 | O41: 2001 | S41: PROGRAMACION 2303 | T41: BOT_CARGOPRO
A42: 5100423889 | B42: 8593 | C42: RA | D42: 46035 | E42: 1125.4 | F42: MXN | G42: 1500034317 | H42: aplicado | I42: AUD PRGX NIVEL SERVICIO 2025 | K42: 46104 | L42: 46035 | M42: 42025 | N42: ZD33 | O42: 2001 | S42: PROGRAMACION 2303 | T42: BOT_CARGOPRO
A43: 5100423890 | B43: 8593 | C43: RA | D43: 46035 | E43: 137365.91 | F43: MXN | G43: 1500034317 | H43: aplicado | I43: AUD PRGX NIVEL SERVICIO 2025 | K43: 46104 | L43: 46035 | M43: 42025 | N43: ZD33 | O43: 2001 | S43: PROGRAMACION 2303 | T43: BOT_CARGOPRO
A44: 5100423891 | B44: 8593 | C44: RA | D44: 46035 | E44: 5473.36 | F44: MXN | G44: 1500034317 | H44: aplicado | I44: AUD PRGX NIVEL SERVICIO 2025 | K44: 46104 | L44: 46035 | M44: 52025 | N44: ZD33 | O44: 2001 | S44: PROGRAMACION 2303 | T44: BOT_CARGOPRO
...

Sheet Reembolsos
F1: 8613844.6 | G1: =F1-G2 -> -4686288.6 | I1: =H2+I2 -> 2468061.7
F2: =SUBTOTAL(9,F4:F1799) -> 15768095 | G2: =SUBTOTAL(9,G4:G1799) -> 13300133 | H2: =SUBTOTAL(9,H4:H1799) -> 810884.12 | I2: =SUBTOTAL(9,I4:I1799) -> 1657177.6
B3: Proveedor | C3: Nombre | D3: Aplicado con Impto | E3: Debe aplicar | F3: Total reembolsar | G3: subtotal | H3: IEPS | I3: IVA | J3: tasa IEPS | K3: tasa IVA | L3: enviado a contraloria | M3: Auditor | O3: comentario auditoria
B4: 696 | C4: INDUSTRIAL NOHRA SA DE CV | D4: 465639.16 | E4: 34914.5 | F4: 430724.66 | G4: 371314.36 | H4: 0 | I4: 59410.298 | J4: 0 | K4: 0.16 | L4: 46111 | M4: Perla | N4: Perla | O4: Monto no procedente informado el 19 de febrero 2026
B5: 3137 | C5: LETICIA PAMMY SA DE CV | D5: 671407.36 | E5: 299401.58 | F5: 372005.78 | G5: 320694.64 | H5: 0 | I5: 51311.14 | J5: 0 | K5: 0.15999999 | L5: 46111 | M5: Perla | N5: Jessica | O5: Monto no procedente informado el 19 de febrero 2026
B6: 48298 | C6: IMPULSORA CAMPIRANO SA DE CV | D6: 400141.22 | E6: 899.3 | F6: 399241.92 | G6: 344174.07 | H6: 0 | I6: 55067.851 | J6: 0 | K6: 0.16 | L6: 46111 | M6: Francisco | N6: Francisco | O6: Monto no procedente informado el 03 de marzo 2026
B7: 311159 | C7: SAUCEDO JAIME GUILLERMO JAVIER | D7: 219055.64 | E7: 0 | F7: 219055.64 | G7: 189068.27 | H7: 0 | I7: 29987.374 | J7: 0 | K7: 0.15860606 | L7: 46111 | M7: Luis | N7: Luis | O7: Monto no procedente informado el 03 de marzo 2026
B8: 8939 | C8: PRODUCTOS DASS SA DE CV | D8: 130896.48 | E8: 19272.7 | F8: 111623.78 | G8: 111623.78 | H8: 0 | I8: 0 | J8: 0 | K8: 0 | L8: 46111 | M8: Yessenia | N8: Samuel | O8: proveedor mandó soporte después del cargo
B9: 325258 | C9: SCHETTINO HERMANOS S DE RL DE CV | D9: 408636.88 | E9: 326883.88 | F9: 81753 | G9: 81753 | H9: 0 | I9: 0 | J9: 0 | K9: 0 | L9: 46111 | M9: Saree | N9: Sareé | O9: proveedor mandó soporte después del cargo
B10: 397984 | C10: COMARKET S.A. DE C.V. | D10: 53357.5 | E10: 0 | F10: 53357.5 | G10: 45997.84 | I10: 7359.66 | J10: 0 | K10: =I10/G10 -> 0.16000012 | L10: 46128 | M10: Yessenia | N10: Yessenia
B11: 397985 | C11: COMARKET S.A. DE C.V. | D11: 53535.64 | E11: 0 | F11: 53535.64 | G11: 46151.41 | I11: 7384.23 | J11: 0 | K11: =I11/G11 -> 0.1600001 | L11: 46128 | M11: Yessenia | N11: Yessenia
B12: 397986 | C12: COMARKET S.A. DE C.V. | D12: 542312.75 | E12: 0 | F12: 542312.75 | G12: 467510.99 | I12: 74801.76 | J12: 0 | K12: =I12/G12 -> 0.16 | L12: 46128 | M12: Yessenia | N12: Yessenia
B13: 397987 | C13: COMARKET S.A. DE C.V. | D13: 327055.94 | E13: 0 | F13: 327055.94 | G13: 281944.78 | I13: 45111.16 | J13: 0 | K13: =I13/G13 -> 0.15999998 | L13: 46128 | M13: Yessenia | N13: Yessenia
B14: 397988 | C14: COMARKET S.A. DE C.V. | D14: 175031.83 | E14: 0 | F14: 175031.83 | G14: 150889.51 | I14: 24142.32 | J14: 0 | K14: =I14/G14 -> 0.15999999 | L14: 46128 | M14: Yessenia | N14: Yessenia
B15: 76471 | C15: NEWELL BRANDS DE MEXICO SA DE CV | D15: 13439248 | F15: 7962909.7 | G15: 6864577.3 | I15: 1098332.4 | J15: 0 | K15: =I15/G15 -> 0.16 | L15: 46136 | M15: Olfi/Raul | N15: Olfi | O15: sistema STIBO errores de captura en unidades de medida INNER PACK y Master PACK
B16: 398024 | C16: PINSA COMERCIAL SA DE CV | D16: 4901364.6 | F16: 1669923.6 | G16: 1669923.6 | H16: 0 | I16: 0 | J16: 0 | K16: 0 | L16: 46142 | M16: Yessenia | N16: Yessenia | O16: Posterior al aviso, se enviaron los soportes correspondientes y se realizó la revisión de la información en conjunto con Controladuría y el área Comercial.
